Workbook

Sheet Template
B1: REPUBLIC OF THE PHILIPPINES
B2: DEPARTMENT OF HEALTH
B4: National Rabies Prevention and Control Program
B5: Animal Bite and Rabies Report Form
B7: Municipality: | H7: Period (Quarter, Year): | J7: Quarter 1, 2026
B9: IMPORTANT REMINDERS 1. Do NOT edit cells highlighted in green as their values are automatically computed. 2. Ensure totals of age, sex, animal bite cases, and biting animals are equal. Ensure all PEP coverage does not exceed 100%. 3. Submit the completed form signed by the Provincial Health Officer (PHO) to idc@mimaropa.doh.gov.ph by the 10th day of the month of the succeeding quarter (e.g., submit 2026 Q1 data by April 10, 2026).
A11: LOCATION (Barangay) | B11: TOTAL POPULATION | C11: ANIMAL BITE CASES | V11: POST-EXPOSURE PROPHYLAXIS (PEP) | AG11: BITING ANIMALS (7) | AN11: HUMAN RABIES CASES
C12: Sex | F12: Age | I12: Category | V12: PEP Completed** | AB12: PEP Coverage | AG12: Type | AJ12: Status | AM12: Total | AN12: Cases (PIDSR c/o RESU) | AO12: Incidence Proportion (per 10⁶)
C13: Male | D13: Female | E13: Total | F13: <15 | G13: >15 | H13: Total | I13: Category I (1) | J13: Category II | O13: Category III | T13: Total PEP eligible | U13: Total (Cat I+II+III) | V13: Category II | X13: Category III | AB13: Category II (4) | AD13: Category III (6) | AF13: Total CCEEV Coverage | AG13: Dog (7a) | AH13: Cat (7b) | AI13: Others (7c) | AJ13: Pet/ Domestic | AK13: Stray/ Free-roaming | AL13: Unknown
J14: PEP eligible | M14: PEP non-eligible* | N14: Total (2) | O14: PEP eligible | R14: PEP non-eligible* | S14: Total (5) | V14: Primary (CCEEV) | W14: Booster (CCEEV) | X14: Primary (CCEEV+RIG) | AA14: Booster (CCEEV only) | AB14: Primary (CCEEV) | AC14: Booster (CCEEV) | AD14: Primary (CCEEV+RIG) (6a) | AE14: Booster (CCEEV only) (6b)
J15: Primary (CCEEV) | K15: Booster (CCEEV) | L15: Total (3) | O15: Primary (CCEEV+RIG) | P15: Booster (CCEEV only) | Q15: Total | X15: ERIG | Y15: HRIG | Z15: Total
E16: =SUM(C16,D16) -> 0 | H16: =F16+G16 -> 0 | L16: =SUM(J16,K16) -> 0 | N16: =SUM(M16) -> 0 | Q16: =SUM(O16,P16) -> 0 | S16: =SUM(Q16,R16) -> 0 | T16: =SUM(L16,Q16) -> 0 | U16: =SUM(I16,N16,S16) -> 0 | Z16: =SUM(X16,Y16) -> 0 | AB16: =IFERROR(V16/J16, 0) -> 0 | AC16: =IFERROR(W16/K16, 0) -> 0 | AD16: =IFERROR(Z16/O16, 0) -> 0 | AE16: =IFERROR(AA16/P16, 0) -> 0 | AF16: =IFERROR(SUM(V16,W16,Z16,AA16)/SUM(L16,Q16), 0) -> 0 | AM16: =SUM(AG16,AH16,AI16) -> 0 | AO16: =IFERROR((AN16/B16)*1000000, 0) -> 0
E17: =SUM(C17,D17) -> 0 | H17: =F17+G17 -> 0 | L17: =SUM(J17,K17) -> 0 | N17: =SUM(M17) -> 0 | Q17: =SUM(O17,P17) -> 0 | S17: =SUM(Q17,R17) -> 0 | T17: =SUM(J17,K17,O17,P17) -> 0 | U17: =SUM(I17,N17,S17) -> 0 | Z17: =SUM(X17,Y17) -> 0 | AB17: =IFERROR(V17/J17, 0) -> 0 | AC17: =IFERROR(W17/K17, 0) -> 0 | AD17: =IFERROR(Z17/O17, 0) -> 0 | AE17: =IFERROR(AA17/P17, 0) -> 0 | AF17: =IFERROR(SUM(V17,W17,Z17,AA17)/SUM(L17,Q17), 0) -> 0 | AM17: =SUM(AG17,AH17,AI17) -> 0 | AO17: =IFERROR((AN17/B17)*1000000, 0) -> 0
E18: =SUM(C18,D18) -> 0 | H18: =F18+G18 -> 0 | L18: =SUM(J18,K18) -> 0 | N18: =SUM(M18) -> 0 | Q18: =SUM(O18,P18) -> 0 | S18: =SUM(Q18,R18) -> 0 | T18: =SUM(J18,K18,O18,P18) -> 0 | U18: =SUM(I18,N18,S18) -> 0 | Z18: =SUM(X18,Y18) -> 0 | AB18: =IFERROR(V18/J18, 0) -> 0 | AC18: =IFERROR(W18/K18, 0) -> 0 | AD18: =IFERROR(Z18/O18, 0) -> 0 | AE18: =IFERROR(AA18/P18, 0) -> 0 | AF18: =IFERROR(SUM(V18,W18,Z18,AA18)/SUM(L18,Q18), 0) -> 0 | AM18: =SUM(AG18,AH18,AI18) -> 0 | AO18: =IFERROR((AN18/B18)*1000000, 0) -> 0
E19: =SUM(C19,D19) -> 0 | H19: =F19+G19 -> 0 | L19: =SUM(J19,K19) -> 0 | N19: =SUM(M19) -> 0 | Q19: =SUM(O19,P19) -> 0 | S19: =SUM(Q19,R19) -> 0 | T19: =SUM(J19,K19,O19,P19) -> 0 | U19: =SUM(I19,N19,S19) -> 0 | Z19: =SUM(X19,Y19) -> 0 | AB19: =IFERROR(V19/J19, 0) -> 0 | AC19: =IFERROR(W19/K19, 0) -> 0 | AD19: =IFERROR(Z19/O19, 0) -> 0 | AE19: =IFERROR(AA19/P19, 0) -> 0 | AF19: =IFERROR(SUM(V19,W19,Z19,AA19)/SUM(L19,Q19), 0) -> 0 | AM19: =SUM(AG19,AH19,AI19) -> 0 | AO19: =IFERROR((AN19/B19)*1000000, 0) -> 0
E20: =SUM(C20,D20) -> 0 | H20: =F20+G20 -> 0 | L20: =SUM(J20,K20) -> 0 | N20: =SUM(M20) -> 0 | Q20: =SUM(O20,P20) -> 0 | S20: =SUM(Q20,R20) -> 0 | T20: =SUM(J20,K20,O20,P20) -> 0 | U20: =SUM(I20,N20,S20) -> 0 | Z20: =SUM(X20,Y20) -> 0 | AB20: =IFERROR(V20/J20, 0) -> 0 | AC20: =IFERROR(W20/K20, 0) -> 0 | AD20: =IFERROR(Z20/O20, 0) -> 0 | AE20: =IFERROR(AA20/P20, 0) -> 0 | AF20: =IFERROR(SUM(V20,W20,Z20,AA20)/SUM(L20,Q20), 0) -> 0 | AM20: =SUM(AG20,AH20,AI20) -> 0 | AO20: =IFERROR((AN20/B20)*1000000, 0) -> 0
E21: =SUM(C21,D21) -> 0 | H21: =F21+G21 -> 0 | L21: =SUM(J21,K21) -> 0 | N21: =SUM(M21) -> 0 | Q21: =SUM(O21,P21) -> 0 | S21: =SUM(Q21,R21) -> 0 | T21: =SUM(J21,K21,O21,P21) -> 0 | U21: =SUM(I21,N21,S21) -> 0 | Z21: =SUM(X21,Y21) -> 0 | AB21: =IFERROR(V21/J21, 0) -> 0 | AC21: =IFERROR(W21/K21, 0) -> 0 | AD21: =IFERROR(Z21/O21, 0) -> 0 | AE21: =IFERROR(AA21/P21, 0) -> 0 | AF21: =IFERROR(SUM(V21,W21,Z21,AA21)/SUM(L21,Q21), 0) -> 0 | AM21: =SUM(AG21,AH21,AI21) -> 0 | AO21: =IFERROR((AN21/B21)*1000000, 0) -> 0
E22: =SUM(C22,D22) -> 0 | H22: =F22+G22 -> 0 | L22: =SUM(J22,K22) -> 0 | N22: =SUM(M22) -> 0 | Q22: =SUM(O22,P22) -> 0 | S22: =SUM(Q22,R22) -> 0 | T22: =SUM(J22,K22,O22,P22) -> 0 | U22: =SUM(I22,N22,S22) -> 0 | Z22: =SUM(X22,Y22) -> 0 | AB22: =IFERROR(V22/J22, 0) -> 0 | AC22: =IFERROR(W22/K22, 0) -> 0 | AD22: =IFERROR(Z22/O22, 0) -> 0 | AE22: =IFERROR(AA22/P22, 0) -> 0 | AF22: =IFERROR(SUM(V22,W22,Z22,AA22)/SUM(L22,Q22), 0) -> 0 | AM22: =SUM(AG22,AH22,AI22) -> 0 | AO22: =IFERROR((AN22/B22)*1000000, 0) -> 0
E23: =SUM(C23,D23) -> 0 | H23: =F23+G23 -> 0 | L23: =SUM(J23,K23) -> 0 | N23: =SUM(M23) -> 0 | Q23: =SUM(O23,P23) -> 0 | S23: =SUM(Q23,R23) -> 0 | T23: =SUM(J23,K23,O23,P23) -> 0 | U23: =SUM(I23,N23,S23) -> 0 | Z23: =SUM(X23,Y23) -> 0 | AB23: =IFERROR(V23/J23, 0) -> 0 | AC23: =IFERROR(W23/K23, 0) -> 0 | AD23: =IFERROR(Z23/O23, 0) -> 0 | AE23: =IFERROR(AA23/P23, 0) -> 0 | AF23: =IFERROR(SUM(V23,W23,Z23,AA23)/SUM(L23,Q23), 0) -> 0 | AM23: =SUM(AG23,AH23,AI23) -> 0 | AO23: =IFERROR((AN23/B23)*1000000, 0) -> 0
E24: =SUM(C24,D24) -> 0 | H24: =F24+G24 -> 0 | L24: =SUM(J24,K24) -> 0 | N24: =SUM(M24) -> 0 | Q24: =SUM(O24,P24) -> 0 | S24: =SUM(Q24,R24) -> 0 | T24: =SUM(J24,K24,O24,P24) -> 0 | U24: =SUM(I24,N24,S24) -> 0 | Z24: =SUM(X24,Y24) -> 0 | AB24: =IFERROR(V24/J24, 0) -> 0 | AC24: =IFERROR(W24/K24, 0) -> 0 | AD24: =IFERROR(Z24/O24, 0) -> 0 | AE24: =IFERROR(AA24/P24, 0) -> 0 | AF24: =IFERROR(SUM(V24,W24,Z24,AA24)/SUM(L24,Q24), 0) -> 0 | AM24: =SUM(AG24,AH24,AI24) -> 0 | AO24: =IFERROR((AN24/B24)*1000000, 0) -> 0
E25: =SUM(C25,D25) -> 0 | H25: =F25+G25 -> 0 | L25: =SUM(J25,K25) -> 0 | N25: =SUM(M25) -> 0 | Q25: =SUM(O25,P25) -> 0 | S25: =SUM(Q25,R25) -> 0 | T25: =SUM(J25,K25,O25,P25) -> 0 | U25: =SUM(I25,N25,S25) -> 0 | Z25: =SUM(X25,Y25) -> 0 | AB25: =IFERROR(V25/J25, 0) -> 0 | AC25: =IFERROR(W25/K25, 0) -> 0 | AD25: =IFERROR(Z25/O25, 0) -> 0 | AE25: =IFERROR(AA25/P25, 0) -> 0 | AF25: =IFERROR(SUM(V25,W25,Z25,AA25)/SUM(L25,Q25), 0) -> 0 | AM25: =SUM(AG25,AH25,AI25) -> 0 | AO25: =IFERROR((AN25/B25)*1000000, 0) -> 0
E26: =SUM(C26,D26) -> 0 | H26: =F26+G26 -> 0 | L26: =SUM(J26,K26) -> 0 | N26: =SUM(M26) -> 0 | Q26: =SUM(O26,P26) -> 0 | S26: =SUM(Q26,R26) -> 0 | T26: =SUM(J26,K26,O26,P26) -> 0 | U26: =SUM(I26,N26,S26) -> 0 | Z26: =SUM(X26,Y26) -> 0 | AB26: =IFERROR(V26/J26, 0) -> 0 | AC26: =IFERROR(W26/K26, 0) -> 0 | AD26: =IFERROR(Z26/O26, 0) -> 0 | AE26: =IFERROR(AA26/P26, 0) -> 0 | AF26: =IFERROR(SUM(V26,W26,Z26,AA26)/SUM(L26,Q26), 0) -> 0 | AM26: =SUM(AG26,AH26,AI26) -> 0 | AO26: =IFERROR((AN26/B26)*1000000, 0) -> 0
E27: =SUM(C27,D27) -> 0 | H27: =F27+G27 -> 0 | L27: =SUM(J27,K27) -> 0 | N27: =SUM(M27) -> 0 | Q27: =SUM(O27,P27) -> 0 | S27: =SUM(Q27,R27) -> 0 | T27: =SUM(J27,K27,O27,P27) -> 0 | U27: =SUM(I27,N27,S27) -> 0 | Z27: =SUM(X27,Y27) -> 0 | AB27: =IFERROR(V27/J27, 0) -> 0 | AC27: =IFERROR(W27/K27, 0) -> 0 | AD27: =IFERROR(Z27/O27, 0) -> 0 | AE27: =IFERROR(AA27/P27, 0) -> 0 | AF27: =IFERROR(SUM(V27,W27,Z27,AA27)/SUM(L27,Q27), 0) -> 0 | AM27: =SUM(AG27,AH27,AI27) -> 0 | AO27: =IFERROR((AN27/B27)*1000000, 0) -> 0
E28: =SUM(C28,D28) -> 0 | H28: =F28+G28 -> 0 | L28: =SUM(J28,K28) -> 0 | N28: =SUM(M28) -> 0 | Q28: =SUM(O28,P28) -> 0 | S28: =SUM(Q28,R28) -> 0 | T28: =SUM(J28,K28,O28,P28) -> 0 | U28: =SUM(I28,N28,S28) -> 0 | Z28: =SUM(X28,Y28) -> 0 | AB28: =IFERROR(V28/J28, 0) -> 0 | AC28: =IFERROR(W28/K28, 0) -> 0 | AD28: =IFERROR(Z28/O28, 0) -> 0 | AE28: =IFERROR(AA28/P28, 0) -> 0 | AF28: =IFERROR(SUM(V28,W28,Z28,AA28)/SUM(L28,Q28), 0) -> 0 | AM28: =SUM(AG28,AH28,AI28) -> 0 | AO28: =IFERROR((AN28/B28)*1000000, 0) -> 0
... E34: =SUM(C34,D34) -> 0 | H34: =F34+G34 -> 0 | L34: =SUM(J34,K34) -> 0 | N34: =SUM(M34) -> 0 | Q34: =SUM(O34,P34) -> 0 | S34: =SUM(Q34,R34) -> 0 | T34: =SUM(J34,K34,O34,P34) -> 0 | U34: =SUM(I34,N34,S34) -> 0 | Z34: =SUM(X34,Y34) -> 0 | AB34: =IFERROR(V34/J34, 0) -> 0 | AC34: =IFERROR(W34/K34, 0) -> 0 | AD34: =IFERROR(Z34/O34, 0) -> 0 | AE34: =IFERROR(AA34/P34, 0) -> 0 | AF34: =IFERROR(SUM(V34,W34,Z34,AA34)/SUM(L34,Q34), 0) -> 0 | AM34: =SUM(AG34,AH34,AI34) -> 0 | AO34: =IFERROR((AN34/B34)*1000000, 0) -> 0
E35: =SUM(C35:D35) -> 0 | H35: =F35+G35 -> 0 | L35: =SUM(J35,K35) -> 0 | N35: =SUM(M35) -> 0 | Q35: =SUM(O35,P35) -> 0 | S35: =SUM(Q35,R35) -> 0 | T35: =SUM(J35,K35,O35,P35) -> 0 | U35: =SUM(I35,N35,S35) -> 0 | Z35: =SUM(X35,Y35) -> 0 | AB35: =IFERROR(V35/J35, 0) -> 0 | AC35: =IFERROR(W35/K35, 0) -> 0 | AD35: =IFERROR(Z35/O35, 0) -> 0 | AE35: =IFERROR(AA35/P35, 0) -> 0 | AF35: =IFERROR(SUM(V35,W35,Z35,AA35)/SUM(L35,Q35), 0) -> 0 | AM35: =SUM(AG35,AH35,AI35) -> 0 | AO35: =IFERROR((AN35/B35)*1000000, 0) -> 0
A36: TOTAL | B36: =SUM(B16:B35) -> 0 | C36: =SUM(C16:C35) -> 0 | D36: =SUM(D16:D35) -> 0 | E36: =SUM(E16:E35) -> 0 | F36: =SUM(F16:F35) -> 0 | G36: =SUM(G16:G35) -> 0 | H36: =SUM(H16:H35) -> 0 | I36: =SUM(I16:I35) -> 0 | ... AA36: =SUM(AA16:AA35) -> 0 | AB36: =IFERROR(V36/J36, 0) -> 0 | AC36: =IFERROR(W36/K36, 0) -> 0 | AD36: =IFERROR(Z36/O36, 0) -> 0 | AE36: =IFERROR(AA36/P36, 0) -> 0 | AF36: =IFERROR(SUM(V36,W36,Z36,AA36)/SUM(L36,Q36), 0) -> 0 | AG36: =SUM(AG16:AG35) -> 0 | AH36: =SUM(AH16:AH35) -> 0 | AI36: =SUM(AI16:AI35) -> 0 | AJ36: =SUM(AJ16:AJ35) -> 0 | AK36: =SUM(AK16:AK35) -> 0 | AL36: =SUM(AL16:AL35) -> 0 | AM36: =SUM(AM16:AM35) -> 0 | AN36: =SUM(AN16:AN35) -> 0 | AO36: =IFERROR((AN36/B36)*1000000, 0) -> 0
A38: DATA VALIDATION | B38: 1 | C38: =IFERROR(__xludf.DUMMYFUNCTION("IF( COUNTUNIQUE($E$36,$H$36,$U$36,$AM$36)=1, ""✅ Totals of sex, age, animal bite cases, and biting animals match"", ""❌ Totals of sex, age, animal bite cases, and biting animals DO NOT match. Please recheck the data."" ) "),"✅ Totals of sex, age, animal bite cases, and biting animals match") -> ✅ Totals of sex, age, animal bite cases, and biting animals match
B39: 2 | C39: =IF( SUMPRODUCT(--(AB16:AF36>1))=0, "✅ PEP Coverage ≤100%", "❌ PEP Coverage cannot exceed 100%. "&SUMPRODUCT(--(AB16:AF36>1))&" cell(s) exceed 100%. Please recheck the data." ) -> ✅ PEP Coverage ≤100%
A40: * PEP (CCEEV ± RIG) non-eligible: Immunologically-naive (Category II): Exposure of a non-immunocompromised individual to a vaccinated animal (as defined in the AO) that is available for observation for 14 days, EXCEPT if any high-risk criteria are present. Previously-immunized (Category II & III): Exposure of a non-immunocompromised individual who completed at least three (3) doses of anti-rabies vaccine within the last six (6) months, EXCEPT if any high-risk criteria are present. High-risk criteria: 1. Vaccinated >6 months ago with ≥3 doses 2. Biting animal cannot be observed, is sick or rabid, dies, or is a bat 3. Wounds in highly innervated areas (neck, head, genital area, hands, toes, or in very close proximity to the CNS) 4. Multiple or deep wounds 5. Patient has uncontrolled co-morbidities 6. Patient is from a hard-to-reach area with infrequent transportation to and from ABTC/ABC **Case count of those who completed PEP (CCEEV ± RIG), not number of doses/vials FORM GUIDE: tinyurl.com/AnimalBiteRFGuide PEP DECISION TREE: tinyurl.com/RabiesPEPDecisionTree | V40: Prepared by: INSERT NAME NRCP Regional Program Manager | AB40: Reviewed by: INSERT NAME Infectious Disease Cluster Head | AH40: Approved by: INSERT NAME CHD Regional Director

Sheet Quarter 1
B1: REPUBLIC OF THE PHILIPPINES
B2: DEPARTMENT OF HEALTH
B4: National Rabies Prevention and Control Program
B5: Animal Bite and Rabies Report Form
B7: Municipality | C7: PHO-PALAWAN | H7: Period (Quarter, Year): | J7: Quarter 1, 2026
B9: IMPORTANT REMINDERS 1. Do NOT edit cells highlighted in green as their values are automatically computed. 2. Ensure totals of age, sex, animal bite cases, and biting animals are equal. Ensure all PEP coverage does not exceed 100%. 3. Submit the completed form signed by the Provincial Health Officer (PHO) to idc@mimaropa.doh.gov.ph by the 10th day of the month of the succeeding quarter (e.g., submit 2026 Q2 data by July 10, 2026).
A11: LOCATION (Barangay) | B11: TOTAL POPULATION | C11: ANIMAL BITE CASES | V11: POST-EXPOSURE PROPHYLAXIS (PEP) | AG11: BITING ANIMALS (7) | AN11: HUMAN RABIES CASES
C12: Sex | F12: Age | I12: Category | V12: PEP Completed** | AB12: PEP Coverage | AG12: Type | AJ12: Status | AM12: Total | AN12: Cases (PIDSR c/o RESU) | AO12: Incidence Proportion (per 10⁶)
C13: Male | D13: Female | E13: Total | F13: <15 | G13: >15 | H13: Total | I13: Category I (1) | J13: Category II | O13: Category III | T13: Total PEP eligible | U13: Total (Cat I+II+III) | V13: Category II | X13: Category III | AB13: Category II (4) | AD13: Category III (6) | AF13: Total CCEEV Coverage | AG13: Dog (7a) | AH13: Cat (7b) | AI13: Others (7c) | AJ13: Pet/ Domestic | AK13: Stray/ Free-roaming | AL13: Unknown
J14: PEP eligible | M14: PEP non-eligible* | N14: Total (2) | O14: PEP eligible | R14: PEP non-eligible* | S14: Total (5) | V14: Primary (CCEEV) | W14: Booster (CCEEV) | X14: Primary (CCEEV+RIG) | AA14: Booster (CCEEV only) | AB14: Primary (CCEEV) | AC14: Booster (CCEEV) | AD14: Primary (CCEEV+RIG) (6a) | AE14: Booster (CCEEV only) (6b)
J15: Primary (CCEEV) | K15: Booster (CCEEV) | L15: Total (3) | O15: Primary (CCEEV+RIG) | P15: Booster (CCEEV only) | Q15: Total | X15: ERIG | Y15: HRIG | Z15: Total
E33: =SUM(C33,D33) -> 0 | H33: =F33+G33 -> 0 | L33: =SUM(J33,K33) -> 0 | N33: =SUM(M33) -> 0 | Q33: =SUM(O33,P33) -> 0 | S33: =SUM(Q33,R33) -> 0 | T33: =SUM(J33,K33,O33,P33) -> 0 | U33: =SUM(I33,N33,S33) -> 0 | Z33: =SUM(X33,Y33) -> 0 | AB33: =IFERROR(V33/J33, 0) -> 0 | AC33: =IFERROR(W33/K33, 0) -> 0 | AD33: =IFERROR(Z33/O33, 0) -> 0 | AE33: =IFERROR(AA33/P33, 0) -> 0 | AF33: =IFERROR(SUM(V33,W33,Z33,AA33)/SUM(L33,Q33), 0) -> 0 | AM33: =SUM(AG33,AH33,AI33) -> 0 | AO33: =IFERROR((AN33/B33)*1000000, 0) -> 0
E34: =SUM(C34,D34) -> 0 | H34: =F34+G34 -> 0 | L34: =SUM(J34,K34) -> 0 | N34: =SUM(M34) -> 0 | Q34: =SUM(O34,P34) -> 0 | S34: =SUM(Q34,R34) -> 0 | T34: =SUM(J34,K34,O34,P34) -> 0 | U34: =SUM(I34,N34,S34) -> 0 | Z34: =SUM(X34,Y34) -> 0 | AB34: =IFERROR(V34/J34, 0) -> 0 | AC34: =IFERROR(W34/K34, 0) -> 0 | AD34: =IFERROR(Z34/O34, 0) -> 0 | AE34: =IFERROR(AA34/P34, 0) -> 0 | AF34: =IFERROR(SUM(V34,W34,Z34,AA34)/SUM(L34,Q34), 0) -> 0 | AM34: =SUM(AG34,AH34,AI34) -> 0 | AO34: =IFERROR((AN34/B34)*1000000, 0) -> 0
E35: =SUM(C35:D35) -> 0 | H35: =F35+G35 -> 0 | L35: =SUM(J35,K35) -> 0 | N35: =SUM(M35) -> 0 | Q35: =SUM(O35,P35) -> 0 | S35: =SUM(Q35,R35) -> 0 | T35: =SUM(J35,K35,O35,P35) -> 0 | U35: =SUM(I35,N35,S35) -> 0 | Z35: =SUM(X35,Y35) -> 0 | AB35: =IFERROR(V35/J35, 0) -> 0 | AC35: =IFERROR(W35/K35, 0) -> 0 | AD35: =IFERROR(Z35/O35, 0) -> 0 | AE35: =IFERROR(AA35/P35, 0) -> 0 | AF35: =IFERROR(SUM(V35,W35,Z35,AA35)/SUM(L35,Q35), 0) -> 0 | AM35: =SUM(AG35,AH35,AI35) -> 0 | AO35: =IFERROR((AN35/B35)*1000000, 0) -> 0
A36: TOTAL | B36: =SUM(B16:B35) -> 0 | C36: =SUM(C16:C35) -> 0 | D36: =SUM(D16:D35) -> 0 | E36: =SUM(E16:E35) -> 0 | F36: =SUM(F16:F35) -> 0 | G36: =SUM(G16:G35) -> 0 | H36: =SUM(H16:H35) -> 0 | I36: =SUM(I16:I35) -> 0 | ... AA36: =SUM(AA16:AA35) -> 0 | AB36: =IFERROR(V36/J36, 0) -> 0 | AC36: =IFERROR(W36/K36, 0) -> 0 | AD36: =IFERROR(Z36/O36, 0) -> 0 | AE36: =IFERROR(AA36/P36, 0) -> 0 | AF36: =IFERROR(SUM(V36,W36,Z36,AA36)/SUM(L36,Q36), 0) -> 0 | AG36: =SUM(AG16:AG35) -> 0 | AH36: =SUM(AH16:AH35) -> 0 | AI36: =SUM(AI16:AI35) -> 0 | AJ36: =SUM(AJ16:AJ35) -> 0 | AK36: =SUM(AK16:AK35) -> 0 | AL36: =SUM(AL16:AL35) -> 0 | AM36: =SUM(AM16:AM35) -> 0 | AN36: =SUM(AN16:AN35) -> 0 | AO36: =IFERROR((AN36/B36)*1000000, 0) -> 0
A38: DATA VALIDATION | B38: 1 | C38: =IFERROR(__xludf.DUMMYFUNCTION("IF( COUNTUNIQUE($E$36,$H$36,$U$36,$AM$36)=1, ""✅ Totals of sex, age, animal bite cases, and biting animals match"", ""❌ Totals of sex, age, animal bite cases, and biting animals DO NOT match. Please recheck the data."" ) "),"✅ Totals of sex, age, animal bite cases, and biting animals match") -> ✅ Totals of sex, age, animal bite cases, and biting animals match
B39: 2 | C39: =IF( SUMPRODUCT(--(AB16:AF36>1))=0, "✅ PEP Coverage ≤100%", "❌ PEP Coverage cannot exceed 100%. "&SUMPRODUCT(--(AB16:AF36>1))&" cell(s) exceed 100%. Please recheck the data." ) -> ✅ PEP Coverage ≤100%
A40: * PEP (CCEEV ± RIG) non-eligible: Immunologically-naive (Category II): Exposure of a non-immunocompromised individual to a vaccinated animal (as defined in the AO) that is available for observation for 14 days, EXCEPT if any high-risk criteria are present. Previously-immunized (Category II & III): Exposure of a non-immunocompromised individual who completed at least three (3) doses of anti-rabies vaccine within the last six (6) months, EXCEPT if any high-risk criteria are present. High-risk criteria: 1. Vaccinated >6 months ago with ≥3 doses 2. Biting animal cannot be observed, is sick or rabid, dies, or is a bat 3. Wounds in highly innervated areas (neck, head, genital area, hands, toes, or in very close proximity to the CNS) 4. Multiple or deep wounds 5. Patient has uncontrolled co-morbidities 6. Patient is from a hard-to-reach area with infrequent transportation to and from ABTC/ABC **Case count of those who completed PEP (CCEEV ± RIG), not number of doses/vials FORM GUIDE: tinyurl.com/AnimalBiteRFGuide PEP DECISION TREE: tinyurl.com/RabiesPEPDecisionTree | V40: Prepared by: INSERT NAME NRCP Regional Program Manager | AB40: Reviewed by: INSERT NAME Infectious Disease Cluster Head | AH40: Approved by: INSERT NAME CHD Regional Director

Sheet Quarter 2
B1: REPUBLIC OF THE PHILIPPINES
B2: DEPARTMENT OF HEALTH
B4: National Rabies Prevention and Control Program
B5: Animal Bite and Rabies Report Form
B7: Municipality | H7: Period (Quarter, Year): | J7: Quarter 2, 2026
B9: IMPORTANT REMINDERS 1. Do NOT edit cells highlighted in green as their values are automatically computed. 2. Ensure totals of age, sex, animal bite cases, and biting animals are equal. Ensure all PEP coverage does not exceed 100%. 3. Submit the completed form signed by the Provincial Health Officer (PHO) to idc@mimaropa.doh.gov.ph by the 10th day of the month of the succeeding quarter (e.g., submit 2026 Q2 data by July 10, 2026).
A11: LOCATION (Barangay) | B11: TOTAL POPULATION | C11: ANIMAL BITE CASES | V11: POST-EXPOSURE PROPHYLAXIS (PEP) | AG11: BITING ANIMALS (7) | AN11: HUMAN RABIES CASES
C12: Sex | F12: Age | I12: Category | V12: PEP Completed** | AB12: PEP Coverage | AG12: Type | AJ12: Status | AM12: Total | AN12: Cases (PIDSR c/o RESU) | AO12: Incidence Proportion (per 10⁶)
C13: Male | D13: Female | E13: Total | F13: <15 | G13: >15 | H13: Total | I13: Category I (1) | J13: Category II | O13: Category III | T13: Total PEP eligible | U13: Total (Cat I+II+III) | V13: Category II | X13: Category III | AB13: Category II (4) | AD13: Category III (6) | AF13: Total CCEEV Coverage | AG13: Dog (7a) | AH13: Cat (7b) | AI13: Others (7c) | AJ13: Pet/ Domestic | AK13: Stray/ Free-roaming | AL13: Unknown
J14: PEP eligible | M14: PEP non-eligible* | N14: Total (2) | O14: PEP eligible | R14: PEP non-eligible* | S14: Total (5) | V14: Primary (CCEEV) | W14: Booster (CCEEV) | X14: Primary (CCEEV+RIG) | AA14: Booster (CCEEV only) | AB14: Primary (CCEEV) | AC14: Booster (CCEEV) | AD14: Primary (CCEEV+RIG) (6a) | AE14: Booster (CCEEV only) (6b)
J15: Primary (CCEEV) | K15: Booster (CCEEV) | L15: Total (3) | O15: Primary (CCEEV+RIG) | P15: Booster (CCEEV only) | Q15: Total | X15: ERIG | Y15: HRIG | Z15: Total
E16: =SUM(C16,D16) -> 0 | H16: =F16+G16 -> 0 | L16: =SUM(J16,K16) -> 0 | N16: =SUM(M16) -> 0 | Q16: =SUM(O16,P16) -> 0 | S16: =SUM(Q16,R16) -> 0 | T16: =SUM(L16,Q16) -> 0 | U16: =SUM(I16,N16,S16) -> 0 | Z16: =SUM(X16,Y16) -> 0 | AB16: =IFERROR(V16/J16, 0) -> 0 | AC16: =IFERROR(W16/K16, 0) -> 0 | AD16: =IFERROR(Z16/O16, 0) -> 0 | AE16: =IFERROR(AA16/P16, 0) -> 0 | AF16: =IFERROR(SUM(V16,W16,Z16,AA16)/SUM(L16,Q16), 0) -> 0 | AM16: =SUM(AG16,AH16,AI16) -> 0 | AO16: =IFERROR((AN16/B16)*1000000, 0) -> 0
E17: =SUM(C17,D17) -> 0 | H17: =F17+G17 -> 0 | L17: =SUM(J17,K17) -> 0 | N17: =SUM(M17) -> 0 | Q17: =SUM(O17,P17) -> 0 | S17: =SUM(Q17,R17) -> 0 | T17: =SUM(J17,K17,O17,P17) -> 0 | U17: =SUM(I17,N17,S17) -> 0 | Z17: =SUM(X17,Y17) -> 0 | AB17: =IFERROR(V17/J17, 0) -> 0 | AC17: =IFERROR(W17/K17, 0) -> 0 | AD17: =IFERROR(Z17/O17, 0) -> 0 | AE17: =IFERROR(AA17/P17, 0) -> 0 | AF17: =IFERROR(SUM(V17,W17,Z17,AA17)/SUM(L17,Q17), 0) -> 0 | AM17: =SUM(AG17,AH17,AI17) -> 0 | AO17: =IFERROR((AN17/B17)*1000000, 0) -> 0
E18: =SUM(C18,D18) -> 0 | H18: =F18+G18 -> 0 | L18: =SUM(J18,K18) -> 0 | N18: =SUM(M18) -> 0 | Q18: =SUM(O18,P18) -> 0 | S18: =SUM(Q18,R18) -> 0 | T18: =SUM(J18,K18,O18,P18) -> 0 | U18: =SUM(I18,N18,S18) -> 0 | Z18: =SUM(X18,Y18) -> 0 | AB18: =IFERROR(V18/J18, 0) -> 0 | AC18: =IFERROR(W18/K18, 0) -> 0 | AD18: =IFERROR(Z18/O18, 0) -> 0 | AE18: =IFERROR(AA18/P18, 0) -> 0 | AF18: =IFERROR(SUM(V18,W18,Z18,AA18)/SUM(L18,Q18), 0) -> 0 | AM18: =SUM(AG18,AH18,AI18) -> 0 | AO18: =IFERROR((AN18/B18)*1000000, 0) -> 0
E19: =SUM(C19,D19) -> 0 | H19: =F19+G19 -> 0 | L19: =SUM(J19,K19) -> 0 | N19: =SUM(M19) -> 0 | Q19: =SUM(O19,P19) -> 0 | S19: =SUM(Q19,R19) -> 0 | T19: =SUM(J19,K19,O19,P19) -> 0 | U19: =SUM(I19,N19,S19) -> 0 | Z19: =SUM(X19,Y19) -> 0 | AB19: =IFERROR(V19/J19, 0) -> 0 | AC19: =IFERROR(W19/K19, 0) -> 0 | AD19: =IFERROR(Z19/O19, 0) -> 0 | AE19: =IFERROR(AA19/P19, 0) -> 0 | AF19: =IFERROR(SUM(V19,W19,Z19,AA19)/SUM(L19,Q19), 0) -> 0 | AM19: =SUM(AG19,AH19,AI19) -> 0 | AO19: =IFERROR((AN19/B19)*1000000, 0) -> 0
E20: =SUM(C20,D20) -> 0 | H20: =F20+G20 -> 0 | L20: =SUM(J20,K20) -> 0 | N20: =SUM(M20) -> 0 | Q20: =SUM(O20,P20) -> 0 | S20: =SUM(Q20,R20) -> 0 | T20: =SUM(J20,K20,O20,P20) -> 0 | U20: =SUM(I20,N20,S20) -> 0 | Z20: =SUM(X20,Y20) -> 0 | AB20: =IFERROR(V20/J20, 0) -> 0 | AC20: =IFERROR(W20/K20, 0) -> 0 | AD20: =IFERROR(Z20/O20, 0) -> 0 | AE20: =IFERROR(AA20/P20, 0) -> 0 | AF20: =IFERROR(SUM(V20,W20,Z20,AA20)/SUM(L20,Q20), 0) -> 0 | AM20: =SUM(AG20,AH20,AI20) -> 0 | AO20: =IFERROR((AN20/B20)*1000000, 0) -> 0
E21: =SUM(C21,D21) -> 0 | H21: =F21+G21 -> 0 | L21: =SUM(J21,K21) -> 0 | N21: =SUM(M21) -> 0 | Q21: =SUM(O21,P21) -> 0 | S21: =SUM(Q21,R21) -> 0 | T21: =SUM(J21,K21,O21,P21) -> 0 | U21: =SUM(I21,N21,S21) -> 0 | Z21: =SUM(X21,Y21) -> 0 | AB21: =IFERROR(V21/J21, 0) -> 0 | AC21: =IFERROR(W21/K21, 0) -> 0 | AD21: =IFERROR(Z21/O21, 0) -> 0 | AE21: =IFERROR(AA21/P21, 0) -> 0 | AF21: =IFERROR(SUM(V21,W21,Z21,AA21)/SUM(L21,Q21), 0) -> 0 | AM21: =SUM(AG21,AH21,AI21) -> 0 | AO21: =IFERROR((AN21/B21)*1000000, 0) -> 0
E22: =SUM(C22,D22) -> 0 | H22: =F22+G22 -> 0 | L22: =SUM(J22,K22) -> 0 | N22: =SUM(M22) -> 0 | Q22: =SUM(O22,P22) -> 0 | S22: =SUM(Q22,R22) -> 0 | T22: =SUM(J22,K22,O22,P22) -> 0 | U22: =SUM(I22,N22,S22) -> 0 | Z22: =SUM(X22,Y22) -> 0 | AB22: =IFERROR(V22/J22, 0) -> 0 | AC22: =IFERROR(W22/K22, 0) -> 0 | AD22: =IFERROR(Z22/O22, 0) -> 0 | AE22: =IFERROR(AA22/P22, 0) -> 0 | AF22: =IFERROR(SUM(V22,W22,Z22,AA22)/SUM(L22,Q22), 0) -> 0 | AM22: =SUM(AG22,AH22,AI22) -> 0 | AO22: =IFERROR((AN22/B22)*1000000, 0) -> 0
E23: =SUM(C23,D23) -> 0 | H23: =F23+G23 -> 0 | L23: =SUM(J23,K23) -> 0 | N23: =SUM(M23) -> 0 | Q23: =SUM(O23,P23) -> 0 | S23: =SUM(Q23,R23) -> 0 | T23: =SUM(J23,K23,O23,P23) -> 0 | U23: =SUM(I23,N23,S23) -> 0 | Z23: =SUM(X23,Y23) -> 0 | AB23: =IFERROR(V23/J23, 0) -> 0 | AC23: =IFERROR(W23/K23, 0) -> 0 | AD23: =IFERROR(Z23/O23, 0) -> 0 | AE23: =IFERROR(AA23/P23, 0) -> 0 | AF23: =IFERROR(SUM(V23,W23,Z23,AA23)/SUM(L23,Q23), 0) -> 0 | AM23: =SUM(AG23,AH23,AI23) -> 0 | AO23: =IFERROR((AN23/B23)*1000000, 0) -> 0
E24: =SUM(C24,D24) -> 0 | H24: =F24+G24 -> 0 | L24: =SUM(J24,K24) -> 0 | N24: =SUM(M24) -> 0 | Q24: =SUM(O24,P24) -> 0 | S24: =SUM(Q24,R24) -> 0 | T24: =SUM(J24,K24,O24,P24) -> 0 | U24: =SUM(I24,N24,S24) -> 0 | Z24: =SUM(X24,Y24) -> 0 | AB24: =IFERROR(V24/J24, 0) -> 0 | AC24: =IFERROR(W24/K24, 0) -> 0 | AD24: =IFERROR(Z24/O24, 0) -> 0 | AE24: =IFERROR(AA24/P24, 0) -> 0 | AF24: =IFERROR(SUM(V24,W24,Z24,AA24)/SUM(L24,Q24), 0) -> 0 | AM24: =SUM(AG24,AH24,AI24) -> 0 | AO24: =IFERROR((AN24/B24)*1000000, 0) -> 0
E25: =SUM(C25,D25) -> 0 | H25: =F25+G25 -> 0 | L25: =SUM(J25,K25) -> 0 | N25: =SUM(M25) -> 0 | Q25: =SUM(O25,P25) -> 0 | S25: =SUM(Q25,R25) -> 0 | T25: =SUM(J25,K25,O25,P25) -> 0 | U25: =SUM(I25,N25,S25) -> 0 | Z25: =SUM(X25,Y25) -> 0 | AB25: =IFERROR(V25/J25, 0) -> 0 | AC25: =IFERROR(W25/K25, 0) -> 0 | AD25: =IFERROR(Z25/O25, 0) -> 0 | AE25: =IFERROR(AA25/P25, 0) -> 0 | AF25: =IFERROR(SUM(V25,W25,Z25,AA25)/SUM(L25,Q25), 0) -> 0 | AM25: =SUM(AG25,AH25,AI25) -> 0 | AO25: =IFERROR((AN25/B25)*1000000, 0) -> 0
E26: =SUM(C26,D26) -> 0 | H26: =F26+G26 -> 0 | L26: =SUM(J26,K26) -> 0 | N26: =SUM(M26) -> 0 | Q26: =SUM(O26,P26) -> 0 | S26: =SUM(Q26,R26) -> 0 | T26: =SUM(J26,K26,O26,P26) -> 0 | U26: =SUM(I26,N26,S26) -> 0 | Z26: =SUM(X26,Y26) -> 0 | AB26: =IFERROR(V26/J26, 0) -> 0 | AC26: =IFERROR(W26/K26, 0) -> 0 | AD26: =IFERROR(Z26/O26, 0) -> 0 | AE26: =IFERROR(AA26/P26, 0) -> 0 | AF26: =IFERROR(SUM(V26,W26,Z26,AA26)/SUM(L26,Q26), 0) -> 0 | AM26: =SUM(AG26,AH26,AI26) -> 0 | AO26: =IFERROR((AN26/B26)*1000000, 0) -> 0
E27: =SUM(C27,D27) -> 0 | H27: =F27+G27 -> 0 | L27: =SUM(J27,K27) -> 0 | N27: =SUM(M27) -> 0 | Q27: =SUM(O27,P27) -> 0 | S27: =SUM(Q27,R27) -> 0 | T27: =SUM(J27,K27,O27,P27) -> 0 | U27: =SUM(I27,N27,S27) -> 0 | Z27: =SUM(X27,Y27) -> 0 | AB27: =IFERROR(V27/J27, 0) -> 0 | AC27: =IFERROR(W27/K27, 0) -> 0 | AD27: =IFERROR(Z27/O27, 0) -> 0 | AE27: =IFERROR(AA27/P27, 0) -> 0 | AF27: =IFERROR(SUM(V27,W27,Z27,AA27)/SUM(L27,Q27), 0) -> 0 | AM27: =SUM(AG27,AH27,AI27) -> 0 | AO27: =IFERROR((AN27/B27)*1000000, 0) -> 0
E28: =SUM(C28,D28) -> 0 | H28: =F28+G28 -> 0 | L28: =SUM(J28,K28) -> 0 | N28: =SUM(M28) -> 0 | Q28: =SUM(O28,P28) -> 0 | S28: =SUM(Q28,R28) -> 0 | T28: =SUM(J28,K28,O28,P28) -> 0 | U28: =SUM(I28,N28,S28) -> 0 | Z28: =SUM(X28,Y28) -> 0 | AB28: =IFERROR(V28/J28, 0) -> 0 | AC28: =IFERROR(W28/K28, 0) -> 0 | AD28: =IFERROR(Z28/O28, 0) -> 0 | AE28: =IFERROR(AA28/P28, 0) -> 0 | AF28: =IFERROR(SUM(V28,W28,Z28,AA28)/SUM(L28,Q28), 0) -> 0 | AM28: =SUM(AG28,AH28,AI28) -> 0 | AO28: =IFERROR((AN28/B28)*1000000, 0) -> 0
... E34: =SUM(C34,D34) -> 0 | H34: =F34+G34 -> 0 | L34: =SUM(J34,K34) -> 0 | N34: =SUM(M34) -> 0 | Q34: =SUM(O34,P34) -> 0 | S34: =SUM(Q34,R34) -> 0 | T34: =SUM(J34,K34,O34,P34) -> 0 | U34: =SUM(I34,N34,S34) -> 0 | Z34: =SUM(X34,Y34) -> 0 | AB34: =IFERROR(V34/J34, 0) -> 0 | AC34: =IFERROR(W34/K34, 0) -> 0 | AD34: =IFERROR(Z34/O34, 0) -> 0 | AE34: =IFERROR(AA34/P34, 0) -> 0 | AF34: =IFERROR(SUM(V34,W34,Z34,AA34)/SUM(L34,Q34), 0) -> 0 | AM34: =SUM(AG34,AH34,AI34) -> 0 | AO34: =IFERROR((AN34/B34)*1000000, 0) -> 0
E35: =SUM(C35:D35) -> 0 | H35: =F35+G35 -> 0 | L35: =SUM(J35,K35) -> 0 | N35: =SUM(M35) -> 0 | Q35: =SUM(O35,P35) -> 0 | S35: =SUM(Q35,R35) -> 0 | T35: =SUM(J35,K35,O35,P35) -> 0 | U35: =SUM(I35,N35,S35) -> 0 | Z35: =SUM(X35,Y35) -> 0 | AB35: =IFERROR(V35/J35, 0) -> 0 | AC35: =IFERROR(W35/K35, 0) -> 0 | AD35: =IFERROR(Z35/O35, 0) -> 0 | AE35: =IFERROR(AA35/P35, 0) -> 0 | AF35: =IFERROR(SUM(V35,W35,Z35,AA35)/SUM(L35,Q35), 0) -> 0 | AM35: =SUM(AG35,AH35,AI35) -> 0 | AO35: =IFERROR((AN35/B35)*1000000, 0) -> 0
A36: TOTAL | B36: =SUM(B16:B35) -> 0 | C36: =SUM(C16:C35) -> 0 | D36: =SUM(D16:D35) -> 0 | E36: =SUM(E16:E35) -> 0 | F36: =SUM(F16:F35) -> 0 | G36: =SUM(G16:G35) -> 0 | H36: =SUM(H16:H35) -> 0 | I36: =SUM(I16:I35) -> 0 | ... AA36: =SUM(AA16:AA35) -> 0 | AB36: =IFERROR(V36/J36, 0) -> 0 | AC36: =IFERROR(W36/K36, 0) -> 0 | AD36: =IFERROR(Z36/O36, 0) -> 0 | AE36: =IFERROR(AA36/P36, 0) -> 0 | AF36: =IFERROR(SUM(V36,W36,Z36,AA36)/SUM(L36,Q36), 0) -> 0 | AG36: =SUM(AG16:AG35) -> 0 | AH36: =SUM(AH16:AH35) -> 0 | AI36: =SUM(AI16:AI35) -> 0 | AJ36: =SUM(AJ16:AJ35) -> 0 | AK36: =SUM(AK16:AK35) -> 0 | AL36: =SUM(AL16:AL35) -> 0 | AM36: =SUM(AM16:AM35) -> 0 | AN36: =SUM(AN16:AN35) -> 0 | AO36: =IFERROR((AN36/B36)*1000000, 0) -> 0
A38: DATA VALIDATION | B38: 1 | C38: =IFERROR(__xludf.DUMMYFUNCTION("IF( COUNTUNIQUE($E$36,$H$36,$U$36,$AM$36)=1, ""✅ Totals of sex, age, animal bite cases, and biting animals match"", ""❌ Totals of sex, age, animal bite cases, and biting animals DO NOT match. Please recheck the data."" ) "),"✅ Totals of sex, age, animal bite cases, and biting animals match") -> ✅ Totals of sex, age, animal bite cases, and biting animals match
B39: 2 | C39: =IF( SUMPRODUCT(--(AB16:AF36>1))=0, "✅ PEP Coverage ≤100%", "❌ PEP Coverage cannot exceed 100%. "&SUMPRODUCT(--(AB16:AF36>1))&" cell(s) exceed 100%. Please recheck the data." ) -> ✅ PEP Coverage ≤100%
A40: * PEP (CCEEV ± RIG) non-eligible: Immunologically-naive (Category II): Exposure of a non-immunocompromised individual to a vaccinated animal (as defined in the AO) that is available for observation for 14 days, EXCEPT if any high-risk criteria are present. Previously-immunized (Category II & III): Exposure of a non-immunocompromised individual who completed at least three (3) doses of anti-rabies vaccine within the last six (6) months, EXCEPT if any high-risk criteria are present. High-risk criteria: 1. Vaccinated >6 months ago with ≥3 doses 2. Biting animal cannot be observed, is sick or rabid, dies, or is a bat 3. Wounds in highly innervated areas (neck, head, genital area, hands, toes, or in very close proximity to the CNS) 4. Multiple or deep wounds 5. Patient has uncontrolled co-morbidities 6. Patient is from a hard-to-reach area with infrequent transportation to and from ABTC/ABC **Case count of those who completed PEP (CCEEV ± RIG), not number of doses/vials FORM GUIDE: tinyurl.com/AnimalBiteRFGuide PEP DECISION TREE: tinyurl.com/RabiesPEPDecisionTree | V40: Prepared by: INSERT NAME NRCP Regional Program Manager | AB40: Reviewed by: INSERT NAME Infectious Disease Cluster Head | AH40: Approved by: INSERT NAME CHD Regional Director

Sheet Quarter 3
B1: REPUBLIC OF THE PHILIPPINES
B2: DEPARTMENT OF HEALTH
B4: National Rabies Prevention and Control Program
B5: Animal Bite and Rabies Report Form
B7: Municipality | H7: Period (Quarter, Year): | J7: Quarter 3, 2026
B9: IMPORTANT REMINDERS 1. Do NOT edit cells highlighted in green as their values are automatically computed. 2. Ensure totals of age, sex, animal bite cases, and biting animals are equal. Ensure all PEP coverage does not exceed 100%. 3. Submit the completed form signed by the Provincial Health Officer (PHO) to idc@mimaropa.doh.gov.ph by the 10th day of the month of the succeeding quarter (e.g., submit 2026 Q3 data by October 10, 2026).
A11: LOCATION (Barangay) | B11: TOTAL POPULATION | C11: ANIMAL BITE CASES | V11: POST-EXPOSURE PROPHYLAXIS (PEP) | AG11: BITING ANIMALS (7) | AN11: HUMAN RABIES CASES
C12: Sex | F12: Age | I12: Category | V12: PEP Completed** | AB12: PEP Coverage | AG12: Type | AJ12: Status | AM12: Total | AN12: Cases (PIDSR c/o RESU) | AO12: Incidence Proportion (per 10⁶)
C13: Male | D13: Female | E13: Total | F13: <15 | G13: >15 | H13: Total | I13: Category I (1) | J13: Category II | O13: Category III | T13: Total PEP eligible | U13: Total (Cat I+II+III) | V13: Category II | X13: Category III | AB13: Category II (4) | AD13: Category III (6) | AF13: Total CCEEV Coverage | AG13: Dog (7a) | AH13: Cat (7b) | AI13: Others (7c) | AJ13: Pet/ Domestic | AK13: Stray/ Free-roaming | AL13: Unknown
J14: PEP eligible | M14: PEP non-eligible* | N14: Total (2) | O14: PEP eligible | R14: PEP non-eligible* | S14: Total (5) | V14: Primary (CCEEV) | W14: Booster (CCEEV) | X14: Primary (CCEEV+RIG) | AA14: Booster (CCEEV only) | AB14: Primary (CCEEV) | AC14: Booster (CCEEV) | AD14: Primary (CCEEV+RIG) (6a) | AE14: Booster (CCEEV only) (6b)
J15: Primary (CCEEV) | K15: Booster (CCEEV) | L15: Total (3) | O15: Primary (CCEEV+RIG) | P15: Booster (CCEEV only) | Q15: Total | X15: ERIG | Y15: HRIG | Z15: Total
E16: =SUM(C16,D16) -> 0 | H16: =F16+G16 -> 0 | L16: =SUM(J16,K16) -> 0 | N16: =SUM(M16) -> 0 | Q16: =SUM(O16,P16) -> 0 | S16: =SUM(Q16,R16) -> 0 | T16: =SUM(L16,Q16) -> 0 | U16: =SUM(I16,N16,S16) -> 0 | Z16: =SUM(X16,Y16) -> 0 | AB16: =IFERROR(V16/J16, 0) -> 0 | AC16: =IFERROR(W16/K16, 0) -> 0 | AD16: =IFERROR(Z16/O16, 0) -> 0 | AE16: =IFERROR(AA16/P16, 0) -> 0 | AF16: =IFERROR(SUM(V16,W16,Z16,AA16)/SUM(L16,Q16), 0) -> 0 | AM16: =SUM(AG16,AH16,AI16) -> 0 | AO16: =IFERROR((AN16/B16)*1000000, 0) -> 0
E17: =SUM(C17,D17) -> 0 | H17: =F17+G17 -> 0 | L17: =SUM(J17,K17) -> 0 | N17: =SUM(M17) -> 0 | Q17: =SUM(O17,P17) -> 0 | S17: =SUM(Q17,R17) -> 0 | T17: =SUM(J17,K17,O17,P17) -> 0 | U17: =SUM(I17,N17,S17) -> 0 | Z17: =SUM(X17,Y17) -> 0 | AB17: =IFERROR(V17/J17, 0) -> 0 | AC17: =IFERROR(W17/K17, 0) -> 0 | AD17: =IFERROR(Z17/O17, 0) -> 0 | AE17: =IFERROR(AA17/P17, 0) -> 0 | AF17: =IFERROR(SUM(V17,W17,Z17,AA17)/SUM(L17,Q17), 0) -> 0 | AM17: =SUM(AG17,AH17,AI17) -> 0 | AO17: =IFERROR((AN17/B17)*1000000, 0) -> 0
E18: =SUM(C18,D18) -> 0 | H18: =F18+G18 -> 0 | L18: =SUM(J18,K18) -> 0 | N18: =SUM(M18) -> 0 | Q18: =SUM(O18,P18) -> 0 | S18: =SUM(Q18,R18) -> 0 | T18: =SUM(J18,K18,O18,P18) -> 0 | U18: =SUM(I18,N18,S18) -> 0 | Z18: =SUM(X18,Y18) -> 0 | AB18: =IFERROR(V18/J18, 0) -> 0 | AC18: =IFERROR(W18/K18, 0) -> 0 | AD18: =IFERROR(Z18/O18, 0) -> 0 | AE18: =IFERROR(AA18/P18, 0) -> 0 | AF18: =IFERROR(SUM(V18,W18,Z18,AA18)/SUM(L18,Q18), 0) -> 0 | AM18: =SUM(AG18,AH18,AI18) -> 0 | AO18: =IFERROR((AN18/B18)*1000000, 0) -> 0
E19: =SUM(C19,D19) -> 0 | H19: =F19+G19 -> 0 | L19: =SUM(J19,K19) -> 0 | N19: =SUM(M19) -> 0 | Q19: =SUM(O19,P19) -> 0 | S19: =SUM(Q19,R19) -> 0 | T19: =SUM(J19,K19,O19,P19) -> 0 | U19: =SUM(I19,N19,S19) -> 0 | Z19: =SUM(X19,Y19) -> 0 | AB19: =IFERROR(V19/J19, 0) -> 0 | AC19: =IFERROR(W19/K19, 0) -> 0 | AD19: =IFERROR(Z19/O19, 0) -> 0 | AE19: =IFERROR(AA19/P19, 0) -> 0 | AF19: =IFERROR(SUM(V19,W19,Z19,AA19)/SUM(L19,Q19), 0) -> 0 | AM19: =SUM(AG19,AH19,AI19) -> 0 | AO19: =IFERROR((AN19/B19)*1000000, 0) -> 0
E20: =SUM(C20,D20) -> 0 | H20: =F20+G20 -> 0 | L20: =SUM(J20,K20) -> 0 | N20: =SUM(M20) -> 0 | Q20: =SUM(O20,P20) -> 0 | S20: =SUM(Q20,R20) -> 0 | T20: =SUM(J20,K20,O20,P20) -> 0 | U20: =SUM(I20,N20,S20) -> 0 | Z20: =SUM(X20,Y20) -> 0 | AB20: =IFERROR(V20/J20, 0) -> 0 | AC20: =IFERROR(W20/K20, 0) -> 0 | AD20: =IFERROR(Z20/O20, 0) -> 0 | AE20: =IFERROR(AA20/P20, 0) -> 0 | AF20: =IFERROR(SUM(V20,W20,Z20,AA20)/SUM(L20,Q20), 0) -> 0 | AM20: =SUM(AG20,AH20,AI20) -> 0 | AO20: =IFERROR((AN20/B20)*1000000, 0) -> 0
E21: =SUM(C21,D21) -> 0 | H21: =F21+G21 -> 0 | L21: =SUM(J21,K21) -> 0 | N21: =SUM(M21) -> 0 | Q21: =SUM(O21,P21) -> 0 | S21: =SUM(Q21,R21) -> 0 | T21: =SUM(J21,K21,O21,P21) -> 0 | U21: =SUM(I21,N21,S21) -> 0 | Z21: =SUM(X21,Y21) -> 0 | AB21: =IFERROR(V21/J21, 0) -> 0 | AC21: =IFERROR(W21/K21, 0) -> 0 | AD21: =IFERROR(Z21/O21, 0) -> 0 | AE21: =IFERROR(AA21/P21, 0) -> 0 | AF21: =IFERROR(SUM(V21,W21,Z21,AA21)/SUM(L21,Q21), 0) -> 0 | AM21: =SUM(AG21,AH21,AI21) -> 0 | AO21: =IFERROR((AN21/B21)*1000000, 0) -> 0
E22: =SUM(C22,D22) -> 0 | H22: =F22+G22 -> 0 | L22: =SUM(J22,K22) -> 0 | N22: =SUM(M22) -> 0 | Q22: =SUM(O22,P22) -> 0 | S22: =SUM(Q22,R22) -> 0 | T22: =SUM(J22,K22,O22,P22) -> 0 | U22: =SUM(I22,N22,S22) -> 0 | Z22: =SUM(X22,Y22) -> 0 | AB22: =IFERROR(V22/J22, 0) -> 0 | AC22: =IFERROR(W22/K22, 0) -> 0 | AD22: =IFERROR(Z22/O22, 0) -> 0 | AE22: =IFERROR(AA22/P22, 0) -> 0 | AF22: =IFERROR(SUM(V22,W22,Z22,AA22)/SUM(L22,Q22), 0) -> 0 | AM22: =SUM(AG22,AH22,AI22) -> 0 | AO22: =IFERROR((AN22/B22)*1000000, 0) -> 0
E23: =SUM(C23,D23) -> 0 | H23: =F23+G23 -> 0 | L23: =SUM(J23,K23) -> 0 | N23: =SUM(M23) -> 0 | Q23: =SUM(O23,P23) -> 0 | S23: =SUM(Q23,R23) -> 0 | T23: =SUM(J23,K23,O23,P23) -> 0 | U23: =SUM(I23,N23,S23) -> 0 | Z23: =SUM(X23,Y23) -> 0 | AB23: =IFERROR(V23/J23, 0) -> 0 | AC23: =IFERROR(W23/K23, 0) -> 0 | AD23: =IFERROR(Z23/O23, 0) -> 0 | AE23: =IFERROR(AA23/P23, 0) -> 0 | AF23: =IFERROR(SUM(V23,W23,Z23,AA23)/SUM(L23,Q23), 0) -> 0 | AM23: =SUM(AG23,AH23,AI23) -> 0 | AO23: =IFERROR((AN23/B23)*1000000, 0) -> 0
E24: =SUM(C24,D24) -> 0 | H24: =F24+G24 -> 0 | L24: =SUM(J24,K24) -> 0 | N24: =SUM(M24) -> 0 | Q24: =SUM(O24,P24) -> 0 | S24: =SUM(Q24,R24) -> 0 | T24: =SUM(J24,K24,O24,P24) -> 0 | U24: =SUM(I24,N24,S24) -> 0 | Z24: =SUM(X24,Y24) -> 0 | AB24: =IFERROR(V24/J24, 0) -> 0 | AC24: =IFERROR(W24/K24, 0) -> 0 | AD24: =IFERROR(Z24/O24, 0) -> 0 | AE24: =IFERROR(AA24/P24, 0) -> 0 | AF24: =IFERROR(SUM(V24,W24,Z24,AA24)/SUM(L24,Q24), 0) -> 0 | AM24: =SUM(AG24,AH24,AI24) -> 0 | AO24: =IFERROR((AN24/B24)*1000000, 0) -> 0
E25: =SUM(C25,D25) -> 0 | H25: =F25+G25 -> 0 | L25: =SUM(J25,K25) -> 0 | N25: =SUM(M25) -> 0 | Q25: =SUM(O25,P25) -> 0 | S25: =SUM(Q25,R25) -> 0 | T25: =SUM(J25,K25,O25,P25) -> 0 | U25: =SUM(I25,N25,S25) -> 0 | Z25: =SUM(X25,Y25) -> 0 | AB25: =IFERROR(V25/J25, 0) -> 0 | AC25: =IFERROR(W25/K25, 0) -> 0 | AD25: =IFERROR(Z25/O25, 0) -> 0 | AE25: =IFERROR(AA25/P25, 0) -> 0 | AF25: =IFERROR(SUM(V25,W25,Z25,AA25)/SUM(L25,Q25), 0) -> 0 | AM25: =SUM(AG25,AH25,AI25) -> 0 | AO25: =IFERROR((AN25/B25)*1000000, 0) -> 0
E26: =SUM(C26,D26) -> 0 | H26: =F26+G26 -> 0 | L26: =SUM(J26,K26) -> 0 | N26: =SUM(M26) -> 0 | Q26: =SUM(O26,P26) -> 0 | S26: =SUM(Q26,R26) -> 0 | T26: =SUM(J26,K26,O26,P26) -> 0 | U26: =SUM(I26,N26,S26) -> 0 | Z26: =SUM(X26,Y26) -> 0 | AB26: =IFERROR(V26/J26, 0) -> 0 | AC26: =IFERROR(W26/K26, 0) -> 0 | AD26: =IFERROR(Z26/O26, 0) -> 0 | AE26: =IFERROR(AA26/P26, 0) -> 0 | AF26: =IFERROR(SUM(V26,W26,Z26,AA26)/SUM(L26,Q26), 0) -> 0 | AM26: =SUM(AG26,AH26,AI26) -> 0 | AO26: =IFERROR((AN26/B26)*1000000, 0) -> 0
E27: =SUM(C27,D27) -> 0 | H27: =F27+G27 -> 0 | L27: =SUM(J27,K27) -> 0 | N27: =SUM(M27) -> 0 | Q27: =SUM(O27,P27) -> 0 | S27: =SUM(Q27,R27) -> 0 | T27: =SUM(J27,K27,O27,P27) -> 0 | U27: =SUM(I27,N27,S27) -> 0 | Z27: =SUM(X27,Y27) -> 0 | AB27: =IFERROR(V27/J27, 0) -> 0 | AC27: =IFERROR(W27/K27, 0) -> 0 | AD27: =IFERROR(Z27/O27, 0) -> 0 | AE27: =IFERROR(AA27/P27, 0) -> 0 | AF27: =IFERROR(SUM(V27,W27,Z27,AA27)/SUM(L27,Q27), 0) -> 0 | AM27: =SUM(AG27,AH27,AI27) -> 0 | AO27: =IFERROR((AN27/B27)*1000000, 0) -> 0
E28: =SUM(C28,D28) -> 0 | H28: =F28+G28 -> 0 | L28: =SUM(J28,K28) -> 0 | N28: =SUM(M28) -> 0 | Q28: =SUM(O28,P28) -> 0 | S28: =SUM(Q28,R28) -> 0 | T28: =SUM(J28,K28,O28,P28) -> 0 | U28: =SUM(I28,N28,S28) -> 0 | Z28: =SUM(X28,Y28) -> 0 | AB28: =IFERROR(V28/J28, 0) -> 0 | AC28: =IFERROR(W28/K28, 0) -> 0 | AD28: =IFERROR(Z28/O28, 0) -> 0 | AE28: =IFERROR(AA28/P28, 0) -> 0 | AF28: =IFERROR(SUM(V28,W28,Z28,AA28)/SUM(L28,Q28), 0) -> 0 | AM28: =SUM(AG28,AH28,AI28) -> 0 | AO28: =IFERROR((AN28/B28)*1000000, 0) -> 0
... E34: =SUM(C34,D34) -> 0 | H34: =F34+G34 -> 0 | L34: =SUM(J34,K34) -> 0 | N34: =SUM(M34) -> 0 | Q34: =SUM(O34,P34) -> 0 | S34: =SUM(Q34,R34) -> 0 | T34: =SUM(J34,K34,O34,P34) -> 0 | U34: =SUM(I34,N34,S34) -> 0 | Z34: =SUM(X34,Y34) -> 0 | AB34: =IFERROR(V34/J34, 0) -> 0 | AC34: =IFERROR(W34/K34, 0) -> 0 | AD34: =IFERROR(Z34/O34, 0) -> 0 | AE34: =IFERROR(AA34/P34, 0) -> 0 | AF34: =IFERROR(SUM(V34,W34,Z34,AA34)/SUM(L34,Q34), 0) -> 0 | AM34: =SUM(AG34,AH34,AI34) -> 0 | AO34: =IFERROR((AN34/B34)*1000000, 0) -> 0
E35: =SUM(C35:D35) -> 0 | H35: =F35+G35 -> 0 | L35: =SUM(J35,K35) -> 0 | N35: =SUM(M35) -> 0 | Q35: =SUM(O35,P35) -> 0 | S35: =SUM(Q35,R35) -> 0 | T35: =SUM(J35,K35,O35,P35) -> 0 | U35: =SUM(I35,N35,S35) -> 0 | Z35: =SUM(X35,Y35) -> 0 | AB35: =IFERROR(V35/J35, 0) -> 0 | AC35: =IFERROR(W35/K35, 0) -> 0 | AD35: =IFERROR(Z35/O35, 0) -> 0 | AE35: =IFERROR(AA35/P35, 0) -> 0 | AF35: =IFERROR(SUM(V35,W35,Z35,AA35)/SUM(L35,Q35), 0) -> 0 | AM35: =SUM(AG35,AH35,AI35) -> 0 | AO35: =IFERROR((AN35/B35)*1000000, 0) -> 0
A36: TOTAL | B36: =SUM(B16:B35) -> 0 | C36: =SUM(C16:C35) -> 0 | D36: =SUM(D16:D35) -> 0 | E36: =SUM(E16:E35) -> 0 | F36: =SUM(F16:F35) -> 0 | G36: =SUM(G16:G35) -> 0 | H36: =SUM(H16:H35) -> 0 | I36: =SUM(I16:I35) -> 0 | ... AA36: =SUM(AA16:AA35) -> 0 | AB36: =IFERROR(V36/J36, 0) -> 0 | AC36: =IFERROR(W36/K36, 0) -> 0 | AD36: =IFERROR(Z36/O36, 0) -> 0 | AE36: =IFERROR(AA36/P36, 0) -> 0 | AF36: =IFERROR(SUM(V36,W36,Z36,AA36)/SUM(L36,Q36), 0) -> 0 | AG36: =SUM(AG16:AG35) -> 0 | AH36: =SUM(AH16:AH35) -> 0 | AI36: =SUM(AI16:AI35) -> 0 | AJ36: =SUM(AJ16:AJ35) -> 0 | AK36: =SUM(AK16:AK35) -> 0 | AL36: =SUM(AL16:AL35) -> 0 | AM36: =SUM(AM16:AM35) -> 0 | AN36: =SUM(AN16:AN35) -> 0 | AO36: =IFERROR((AN36/B36)*1000000, 0) -> 0
A38: DATA VALIDATION | B38: 1 | C38: =IFERROR(__xludf.DUMMYFUNCTION("IF( COUNTUNIQUE($E$36,$H$36,$U$36,$AM$36)=1, ""✅ Totals of sex, age, animal bite cases, and biting animals match"", ""❌ Totals of sex, age, animal bite cases, and biting animals DO NOT match. Please recheck the data."" ) "),"✅ Totals of sex, age, animal bite cases, and biting animals match") -> ✅ Totals of sex, age, animal bite cases, and biting animals match
B39: 2 | C39: =IF( SUMPRODUCT(--(AB16:AF36>1))=0, "✅ PEP Coverage ≤100%", "❌ PEP Coverage cannot exceed 100%. "&SUMPRODUCT(--(AB16:AF36>1))&" cell(s) exceed 100%. Please recheck the data." ) -> ✅ PEP Coverage ≤100%
A40: * PEP (CCEEV ± RIG) non-eligible: Immunologically-naive (Category II): Exposure of a non-immunocompromised individual to a vaccinated animal (as defined in the AO) that is available for observation for 14 days, EXCEPT if any high-risk criteria are present. Previously-immunized (Category II & III): Exposure of a non-immunocompromised individual who completed at least three (3) doses of anti-rabies vaccine within the last six (6) months, EXCEPT if any high-risk criteria are present. High-risk criteria: 1. Vaccinated >6 months ago with ≥3 doses 2. Biting animal cannot be observed, is sick or rabid, dies, or is a bat 3. Wounds in highly innervated areas (neck, head, genital area, hands, toes, or in very close proximity to the CNS) 4. Multiple or deep wounds 5. Patient has uncontrolled co-morbidities 6. Patient is from a hard-to-reach area with infrequent transportation to and from ABTC/ABC **Case count of those who completed PEP (CCEEV ± RIG), not number of doses/vials FORM GUIDE: tinyurl.com/AnimalBiteRFGuide PEP DECISION TREE: tinyurl.com/RabiesPEPDecisionTree | V40: Prepared by: INSERT NAME NRCP Regional Program Manager | AB40: Reviewed by: INSERT NAME Infectious Disease Cluster Head | AH40: Approved by: INSERT NAME CHD Regional Director

Sheet Quarter 4
B1: REPUBLIC OF THE PHILIPPINES
B2: DEPARTMENT OF HEALTH
B4: National Rabies Prevention and Control Program
B5: Animal Bite and Rabies Report Form
B7: Municipality: | H7: Period (Quarter, Year): | J7: Quarter 4, 2026
B9: IMPORTANT REMINDERS 1. Do NOT edit cells highlighted in green as their values are automatically computed. 2. Ensure totals of age, sex, animal bite cases, and biting animals are equal. Ensure all PEP coverage does not exceed 100%. 3. Submit the completed form signed by the Provincial Health Officer (PHO) to idc@mimaropa.doh.gov.ph by the 10th day of the month of the succeeding quarter (e.g., submit 2026 4 data by January 10, 2027).
A11: LOCATION (Barangay) | B11: TOTAL POPULATION | C11: ANIMAL BITE CASES | V11: POST-EXPOSURE PROPHYLAXIS (PEP) | AG11: BITING ANIMALS (7) | AN11: HUMAN RABIES CASES
C12: Sex | F12: Age | I12: Category | V12: PEP Completed** | AB12: PEP Coverage | AG12: Type | AJ12: Status | AM12: Total | AN12: Cases (PIDSR c/o RESU) | AO12: Incidence Proportion (per 10⁶)
C13: Male | D13: Female | E13: Total | F13: <15 | G13: >15 | H13: Total | I13: Category I (1) | J13: Category II | O13: Category III | T13: Total PEP eligible | U13: Total (Cat I+II+III) | V13: Category II | X13: Category III | AB13: Category II (4) | AD13: Category III (6) | AF13: Total CCEEV Coverage | AG13: Dog (7a) | AH13: Cat (7b) | AI13: Others (7c) | AJ13: Pet/ Domestic | AK13: Stray/ Free-roaming | AL13: Unknown
J14: PEP eligible | M14: PEP non-eligible* | N14: Total (2) | O14: PEP eligible | R14: PEP non-eligible* | S14: Total (5) | V14: Primary (CCEEV) | W14: Booster (CCEEV) | X14: Primary (CCEEV+RIG) | AA14: Booster (CCEEV only) | AB14: Primary (CCEEV) | AC14: Booster (CCEEV) | AD14: Primary (CCEEV+RIG) (6a) | AE14: Booster (CCEEV only) (6b)
J15: Primary (CCEEV) | K15: Booster (CCEEV) | L15: Total (3) | O15: Primary (CCEEV+RIG) | P15: Booster (CCEEV only) | Q15: Total | X15: ERIG | Y15: HRIG | Z15: Total
E16: =SUM(C16,D16) -> 0 | H16: =F16+G16 -> 0 | L16: =SUM(J16,K16) -> 0 | N16: =SUM(M16) -> 0 | Q16: =SUM(O16,P16) -> 0 | S16: =SUM(Q16,R16) -> 0 | T16: =SUM(L16,Q16) -> 0 | U16: =SUM(I16,N16,S16) -> 0 | Z16: =SUM(X16,Y16) -> 0 | AB16: =IFERROR(V16/J16, 0) -> 0 | AC16: =IFERROR(W16/K16, 0) -> 0 | AD16: =IFERROR(Z16/O16, 0) -> 0 | AE16: =IFERROR(AA16/P16, 0) -> 0 | AF16: =IFERROR(SUM(V16,W16,Z16,AA16)/SUM(L16,Q16), 0) -> 0 | AM16: =SUM(AG16,AH16,AI16) -> 0 | AO16: =IFERROR((AN16/B16)*1000000, 0) -> 0
E17: =SUM(C17,D17) -> 0 | H17: =F17+G17 -> 0 | L17: =SUM(J17,K17) -> 0 | N17: =SUM(M17) -> 0 | Q17: =SUM(O17,P17) -> 0 | S17: =SUM(Q17,R17) -> 0 | T17: =SUM(J17,K17,O17,P17) -> 0 | U17: =SUM(I17,N17,S17) -> 0 | Z17: =SUM(X17,Y17) -> 0 | AB17: =IFERROR(V17/J17, 0) -> 0 | AC17: =IFERROR(W17/K17, 0) -> 0 | AD17: =IFERROR(Z17/O17, 0) -> 0 | AE17: =IFERROR(AA17/P17, 0) -> 0 | AF17: =IFERROR(SUM(V17,W17,Z17,AA17)/SUM(L17,Q17), 0) -> 0 | AM17: =SUM(AG17,AH17,AI17) -> 0 | AO17: =IFERROR((AN17/B17)*1000000, 0) -> 0
E18: =SUM(C18,D18) -> 0 | H18: =F18+G18 -> 0 | L18: =SUM(J18,K18) -> 0 | N18: =SUM(M18) -> 0 | Q18: =SUM(O18,P18) -> 0 | S18: =SUM(Q18,R18) -> 0 | T18: =SUM(J18,K18,O18,P18) -> 0 | U18: =SUM(I18,N18,S18) -> 0 | Z18: =SUM(X18,Y18) -> 0 | AB18: =IFERROR(V18/J18, 0) -> 0 | AC18: =IFERROR(W18/K18, 0) -> 0 | AD18: =IFERROR(Z18/O18, 0) -> 0 | AE18: =IFERROR(AA18/P18, 0) -> 0 | AF18: =IFERROR(SUM(V18,W18,Z18,AA18)/SUM(L18,Q18), 0) -> 0 | AM18: =SUM(AG18,AH18,AI18) -> 0 | AO18: =IFERROR((AN18/B18)*1000000, 0) -> 0
E19: =SUM(C19,D19) -> 0 | H19: =F19+G19 -> 0 | L19: =SUM(J19,K19) -> 0 | N19: =SUM(M19) -> 0 | Q19: =SUM(O19,P19) -> 0 | S19: =SUM(Q19,R19) -> 0 | T19: =SUM(J19,K19,O19,P19) -> 0 | U19: =SUM(I19,N19,S19) -> 0 | Z19: =SUM(X19,Y19) -> 0 | AB19: =IFERROR(V19/J19, 0) -> 0 | AC19: =IFERROR(W19/K19, 0) -> 0 | AD19: =IFERROR(Z19/O19, 0) -> 0 | AE19: =IFERROR(AA19/P19, 0) -> 0 | AF19: =IFERROR(SUM(V19,W19,Z19,AA19)/SUM(L19,Q19), 0) -> 0 | AM19: =SUM(AG19,AH19,AI19) -> 0 | AO19: =IFERROR((AN19/B19)*1000000, 0) -> 0
E20: =SUM(C20,D20) -> 0 | H20: =F20+G20 -> 0 | L20: =SUM(J20,K20) -> 0 | N20: =SUM(M20) -> 0 | Q20: =SUM(O20,P20) -> 0 | S20: =SUM(Q20,R20) -> 0 | T20: =SUM(J20,K20,O20,P20) -> 0 | U20: =SUM(I20,N20,S20) -> 0 | Z20: =SUM(X20,Y20) -> 0 | AB20: =IFERROR(V20/J20, 0) -> 0 | AC20: =IFERROR(W20/K20, 0) -> 0 | AD20: =IFERROR(Z20/O20, 0) -> 0 | AE20: =IFERROR(AA20/P20, 0) -> 0 | AF20: =IFERROR(SUM(V20,W20,Z20,AA20)/SUM(L20,Q20), 0) -> 0 | AM20: =SUM(AG20,AH20,AI20) -> 0 | AO20: =IFERROR((AN20/B20)*1000000, 0) -> 0
E21: =SUM(C21,D21) -> 0 | H21: =F21+G21 -> 0 | L21: =SUM(J21,K21) -> 0 | N21: =SUM(M21) -> 0 | Q21: =SUM(O21,P21) -> 0 | S21: =SUM(Q21,R21) -> 0 | T21: =SUM(J21,K21,O21,P21) -> 0 | U21: =SUM(I21,N21,S21) -> 0 | Z21: =SUM(X21,Y21) -> 0 | AB21: =IFERROR(V21/J21, 0) -> 0 | AC21: =IFERROR(W21/K21, 0) -> 0 | AD21: =IFERROR(Z21/O21, 0) -> 0 | AE21: =IFERROR(AA21/P21, 0) -> 0 | AF21: =IFERROR(SUM(V21,W21,Z21,AA21)/SUM(L21,Q21), 0) -> 0 | AM21: =SUM(AG21,AH21,AI21) -> 0 | AO21: =IFERROR((AN21/B21)*1000000, 0) -> 0
E22: =SUM(C22,D22) -> 0 | H22: =F22+G22 -> 0 | L22: =SUM(J22,K22) -> 0 | N22: =SUM(M22) -> 0 | Q22: =SUM(O22,P22) -> 0 | S22: =SUM(Q22,R22) -> 0 | T22: =SUM(J22,K22,O22,P22) -> 0 | U22: =SUM(I22,N22,S22) -> 0 | Z22: =SUM(X22,Y22) -> 0 | AB22: =IFERROR(V22/J22, 0) -> 0 | AC22: =IFERROR(W22/K22, 0) -> 0 | AD22: =IFERROR(Z22/O22, 0) -> 0 | AE22: =IFERROR(AA22/P22, 0) -> 0 | AF22: =IFERROR(SUM(V22,W22,Z22,AA22)/SUM(L22,Q22), 0) -> 0 | AM22: =SUM(AG22,AH22,AI22) -> 0 | AO22: =IFERROR((AN22/B22)*1000000, 0) -> 0
E23: =SUM(C23,D23) -> 0 | H23: =F23+G23 -> 0 | L23: =SUM(J23,K23) -> 0 | N23: =SUM(M23) -> 0 | Q23: =SUM(O23,P23) -> 0 | S23: =SUM(Q23,R23) -> 0 | T23: =SUM(J23,K23,O23,P23) -> 0 | U23: =SUM(I23,N23,S23) -> 0 | Z23: =SUM(X23,Y23) -> 0 | AB23: =IFERROR(V23/J23, 0) -> 0 | AC23: =IFERROR(W23/K23, 0) -> 0 | AD23: =IFERROR(Z23/O23, 0) -> 0 | AE23: =IFERROR(AA23/P23, 0) -> 0 | AF23: =IFERROR(SUM(V23,W23,Z23,AA23)/SUM(L23,Q23), 0) -> 0 | AM23: =SUM(AG23,AH23,AI23) -> 0 | AO23: =IFERROR((AN23/B23)*1000000, 0) -> 0
E24: =SUM(C24,D24) -> 0 | H24: =F24+G24 -> 0 | L24: =SUM(J24,K24) -> 0 | N24: =SUM(M24) -> 0 | Q24: =SUM(O24,P24) -> 0 | S24: =SUM(Q24,R24) -> 0 | T24: =SUM(J24,K24,O24,P24) -> 0 | U24: =SUM(I24,N24,S24) -> 0 | Z24: =SUM(X24,Y24) -> 0 | AB24: =IFERROR(V24/J24, 0) -> 0 | AC24: =IFERROR(W24/K24, 0) -> 0 | AD24: =IFERROR(Z24/O24, 0) -> 0 | AE24: =IFERROR(AA24/P24, 0) -> 0 | AF24: =IFERROR(SUM(V24,W24,Z24,AA24)/SUM(L24,Q24), 0) -> 0 | AM24: =SUM(AG24,AH24,AI24) -> 0 | AO24: =IFERROR((AN24/B24)*1000000, 0) -> 0
E25: =SUM(C25,D25) -> 0 | H25: =F25+G25 -> 0 | L25: =SUM(J25,K25) -> 0 | N25: =SUM(M25) -> 0 | Q25: =SUM(O25,P25) -> 0 | S25: =SUM(Q25,R25) -> 0 | T25: =SUM(J25,K25,O25,P25) -> 0 | U25: =SUM(I25,N25,S25) -> 0 | Z25: =SUM(X25,Y25) -> 0 | AB25: =IFERROR(V25/J25, 0) -> 0 | AC25: =IFERROR(W25/K25, 0) -> 0 | AD25: =IFERROR(Z25/O25, 0) -> 0 | AE25: =IFERROR(AA25/P25, 0) -> 0 | AF25: =IFERROR(SUM(V25,W25,Z25,AA25)/SUM(L25,Q25), 0) -> 0 | AM25: =SUM(AG25,AH25,AI25) -> 0 | AO25: =IFERROR((AN25/B25)*1000000, 0) -> 0
E26: =SUM(C26,D26) -> 0 | H26: =F26+G26 -> 0 | L26: =SUM(J26,K26) -> 0 | N26: =SUM(M26) -> 0 | Q26: =SUM(O26,P26) -> 0 | S26: =SUM(Q26,R26) -> 0 | T26: =SUM(J26,K26,O26,P26) -> 0 | U26: =SUM(I26,N26,S26) -> 0 | Z26: =SUM(X26,Y26) -> 0 | AB26: =IFERROR(V26/J26, 0) -> 0 | AC26: =IFERROR(W26/K26, 0) -> 0 | AD26: =IFERROR(Z26/O26, 0) -> 0 | AE26: =IFERROR(AA26/P26, 0) -> 0 | AF26: =IFERROR(SUM(V26,W26,Z26,AA26)/SUM(L26,Q26), 0) -> 0 | AM26: =SUM(AG26,AH26,AI26) -> 0 | AO26: =IFERROR((AN26/B26)*1000000, 0) -> 0
E27: =SUM(C27,D27) -> 0 | H27: =F27+G27 -> 0 | L27: =SUM(J27,K27) -> 0 | N27: =SUM(M27) -> 0 | Q27: =SUM(O27,P27) -> 0 | S27: =SUM(Q27,R27) -> 0 | T27: =SUM(J27,K27,O27,P27) -> 0 | U27: =SUM(I27,N27,S27) -> 0 | Z27: =SUM(X27,Y27) -> 0 | AB27: =IFERROR(V27/J27, 0) -> 0 | AC27: =IFERROR(W27/K27, 0) -> 0 | AD27: =IFERROR(Z27/O27, 0) -> 0 | AE27: =IFERROR(AA27/P27, 0) -> 0 | AF27: =IFERROR(SUM(V27,W27,Z27,AA27)/SUM(L27,Q27), 0) -> 0 | AM27: =SUM(AG27,AH27,AI27) -> 0 | AO27: =IFERROR((AN27/B27)*1000000, 0) -> 0
E28: =SUM(C28,D28) -> 0 | H28: =F28+G28 -> 0 | L28: =SUM(J28,K28) -> 0 | N28: =SUM(M28) -> 0 | Q28: =SUM(O28,P28) -> 0 | S28: =SUM(Q28,R28) -> 0 | T28: =SUM(J28,K28,O28,P28) -> 0 | U28: =SUM(I28,N28,S28) -> 0 | Z28: =SUM(X28,Y28) -> 0 | AB28: =IFERROR(V28/J28, 0) -> 0 | AC28: =IFERROR(W28/K28, 0) -> 0 | AD28: =IFERROR(Z28/O28, 0) -> 0 | AE28: =IFERROR(AA28/P28, 0) -> 0 | AF28: =IFERROR(SUM(V28,W28,Z28,AA28)/SUM(L28,Q28), 0) -> 0 | AM28: =SUM(AG28,AH28,AI28) -> 0 | AO28: =IFERROR((AN28/B28)*1000000, 0) -> 0
... E34: =SUM(C34,D34) -> 0 | H34: =F34+G34 -> 0 | L34: =SUM(J34,K34) -> 0 | N34: =SUM(M34) -> 0 | Q34: =SUM(O34,P34) -> 0 | S34: =SUM(Q34,R34) -> 0 | T34: =SUM(J34,K34,O34,P34) -> 0 | U34: =SUM(I34,N34,S34) -> 0 | Z34: =SUM(X34,Y34) -> 0 | AB34: =IFERROR(V34/J34, 0) -> 0 | AC34: =IFERROR(W34/K34, 0) -> 0 | AD34: =IFERROR(Z34/O34, 0) -> 0 | AE34: =IFERROR(AA34/P34, 0) -> 0 | AF34: =IFERROR(SUM(V34,W34,Z34,AA34)/SUM(L34,Q34), 0) -> 0 | AM34: =SUM(AG34,AH34,AI34) -> 0 | AO34: =IFERROR((AN34/B34)*1000000, 0) -> 0
E35: =SUM(C35:D35) -> 0 | H35: =F35+G35 -> 0 | L35: =SUM(J35,K35) -> 0 | N35: =SUM(M35) -> 0 | Q35: =SUM(O35,P35) -> 0 | S35: =SUM(Q35,R35) -> 0 | T35: =SUM(J35,K35,O35,P35) -> 0 | U35: =SUM(I35,N35,S35) -> 0 | Z35: =SUM(X35,Y35) -> 0 | AB35: =IFERROR(V35/J35, 0) -> 0 | AC35: =IFERROR(W35/K35, 0) -> 0 | AD35: =IFERROR(Z35/O35, 0) -> 0 | AE35: =IFERROR(AA35/P35, 0) -> 0 | AF35: =IFERROR(SUM(V35,W35,Z35,AA35)/SUM(L35,Q35), 0) -> 0 | AM35: =SUM(AG35,AH35,AI35) -> 0 | AO35: =IFERROR((AN35/B35)*1000000, 0) -> 0
A36: TOTAL | B36: =SUM(B16:B35) -> 0 | C36: =SUM(C16:C35) -> 0 | D36: =SUM(D16:D35) -> 0 | E36: =SUM(E16:E35) -> 0 | F36: =SUM(F16:F35) -> 0 | G36: =SUM(G16:G35) -> 0 | H36: =SUM(H16:H35) -> 0 | I36: =SUM(I16:I35) -> 0 | ... AA36: =SUM(AA16:AA35) -> 0 | AB36: =IFERROR(V36/J36, 0) -> 0 | AC36: =IFERROR(W36/K36, 0) -> 0 | AD36: =IFERROR(Z36/O36, 0) -> 0 | AE36: =IFERROR(AA36/P36, 0) -> 0 | AF36: =IFERROR(SUM(V36,W36,Z36,AA36)/SUM(L36,Q36), 0) -> 0 | AG36: =SUM(AG16:AG35) -> 0 | AH36: =SUM(AH16:AH35) -> 0 | AI36: =SUM(AI16:AI35) -> 0 | AJ36: =SUM(AJ16:AJ35) -> 0 | AK36: =SUM(AK16:AK35) -> 0 | AL36: =SUM(AL16:AL35) -> 0 | AM36: =SUM(AM16:AM35) -> 0 | AN36: =SUM(AN16:AN35) -> 0 | AO36: =IFERROR((AN36/B36)*1000000, 0) -> 0
A38: DATA VALIDATION | B38: 1 | C38: =IFERROR(__xludf.DUMMYFUNCTION("IF( COUNTUNIQUE($E$36,$H$36,$U$36,$AM$36)=1, ""✅ Totals of sex, age, animal bite cases, and biting animals match"", ""❌ Totals of sex, age, animal bite cases, and biting animals DO NOT match. Please recheck the data."" ) "),"✅ Totals of sex, age, animal bite cases, and biting animals match") -> ✅ Totals of sex, age, animal bite cases, and biting animals match
B39: 2 | C39: =IF( SUMPRODUCT(--(AB16:AF36>1))=0, "✅ PEP Coverage ≤100%", "❌ PEP Coverage cannot exceed 100%. "&SUMPRODUCT(--(AB16:AF36>1))&" cell(s) exceed 100%. Please recheck the data." ) -> ✅ PEP Coverage ≤100%
A40: * PEP (CCEEV ± RIG) non-eligible: Immunologically-naive (Category II): Exposure of a non-immunocompromised individual to a vaccinated animal (as defined in the AO) that is available for observation for 14 days, EXCEPT if any high-risk criteria are present. Previously-immunized (Category II & III): Exposure of a non-immunocompromised individual who completed at least three (3) doses of anti-rabies vaccine within the last six (6) months, EXCEPT if any high-risk criteria are present. High-risk criteria: 1. Vaccinated >6 months ago with ≥3 doses 2. Biting animal cannot be observed, is sick or rabid, dies, or is a bat 3. Wounds in highly innervated areas (neck, head, genital area, hands, toes, or in very close proximity to the CNS) 4. Multiple or deep wounds 5. Patient has uncontrolled co-morbidities 6. Patient is from a hard-to-reach area with infrequent transportation to and from ABTC/ABC **Case count of those who completed PEP (CCEEV ± RIG), not number of doses/vials FORM GUIDE: tinyurl.com/AnimalBiteRFGuide PEP DECISION TREE: tinyurl.com/RabiesPEPDecisionTree | V40: Prepared by: INSERT NAME NRCP Regional Program Manager | AB40: Reviewed by: INSERT NAME Infectious Disease Cluster Head | AH40: Approved by: INSERT NAME CHD Regional Director

Sheet Summary
B1: REPUBLIC OF THE PHILIPPINES
B2: DEPARTMENT OF HEALTH
B4: National Rabies Prevention and Control Program
B5: Animal Bite and Rabies Report Form
B7: Municipality: | H7: Period (Quarter, Year): | J7: Annual Summary
B9: IMPORTANT REMINDERS 1. Do NOT edit cells highlighted in green as their values are automatically computed. 2. Ensure totals of age, sex, animal bite cases, and biting animals are equal. Ensure all PEP coverage does not exceed 100%. 3. Submit the completed form signed by the Provincial Health Officer (PHO) to idc@mimaropa.doh.gov.ph by the 10th day of the month of the succeeding quarter (e.g., submit 2026 Q4 data by January 10, 2027).
A11: LOCATION (Barangay) | B11: TOTAL POPULATION | C11: ANIMAL BITE CASES | V11: POST-EXPOSURE PROPHYLAXIS (PEP) | AG11: BITING ANIMALS (7) | AN11: HUMAN RABIES CASES
C12: Sex | F12: Age | I12: Category | V12: PEP Completed** | AB12: PEP Coverage | AG12: Type | AJ12: Status | AM12: Total | AN12: Cases (PIDSR c/o RESU) | AO12: Incidence Proportion (per 10⁶)
C13: Male | D13: Female | E13: Total | F13: <15 | G13: >15 | H13: Total | I13: Category I (1) | J13: Category II | O13: Category III | T13: Total PEP eligible | U13: Total (Cat I+II+III) | V13: Category II | X13: Category III | AB13: Category II (4) | AD13: Category III (6) | AF13: Total CCEEV Coverage | AG13: Dog (7a) | AH13: Cat (7b) | AI13: Others (7c) | AJ13: Pet/ Domestic | AK13: Stray/ Free-roaming | AL13: Unknown
J14: PEP eligible | M14: PEP non-eligible* | N14: Total (2) | O14: PEP eligible | R14: PEP non-eligible* | S14: Total (5) | V14: Primary (CCEEV) | W14: Booster (CCEEV) | X14: Primary (CCEEV+RIG) | AA14: Booster (CCEEV only) | AB14: Primary (CCEEV) | AC14: Booster (CCEEV) | AD14: Primary (CCEEV+RIG) (6a) | AE14: Booster (CCEEV only) (6b)
J15: Primary (CCEEV) | K15: Booster (CCEEV) | L15: Total (3) | O15: Primary (CCEEV+RIG) | P15: Booster (CCEEV only) | Q15: Total | X15: ERIG | Y15: HRIG | Z15: Total
B16: ='Quarter 4'!B16 -> 0 | C16: =SUM(#REF!, 'Quarter 2'!C16, 'Quarter 3'!C16, 'Quarter 4'!C16) -> #REF! | D16: =SUM(#REF!, 'Quarter 2'!D16, 'Quarter 3'!D16, 'Quarter 4'!D16) -> #REF! | E16: =SUM(C16,D16) -> #REF! | F16: =SUM(#REF!, 'Quarter 2'!F16, 'Quarter 3'!F16, 'Quarter 4'!F16) -> #REF! | G16: =SUM(#REF!, 'Quarter 2'!G16, 'Quarter 3'!G16, 'Quarter 4'!G16) -> #REF! | H16: =F16+G16 -> #REF! | I16: =SUM(#REF!, 'Quarter 2'!I16, 'Quarter 3'!I16, 'Quarter 4'!I16) -> #REF! | J16: =SUM(#REF!, 'Quarter 2'!J16, 'Quarter 3'!J16, 'Quarter 4'!J16) -> #REF! | K16: =SUM(#REF!, 'Quarter 2'!K16, 'Quarter 3'!K16, 'Quarter 4'!K16) -> #REF! | L16: =SUM(J16,K16) -> #REF! | M16: =SUM(#REF!, 'Quarter 2'!M16, 'Quarter 3'!M16, 'Quarter 4'!M16) -> #REF! | N16: =SUM(M16) -> #REF! | O16: =SUM(#REF!, 'Quarter 2'!O16, 'Quarter 3'!O16, 'Quarter 4'!O16) -> #REF! | P16: =SUM(#REF!, 'Quarter 2'!P16, 'Quarter 3'!P16, 'Quarter 4'!P16) -> #REF! | Q16: =SUM(O16,P16) -> #REF! | R16: =SUM(#REF!, 'Quarter 2'!R16, 'Quarter 3'!R16, 'Quarter 4'!R16) -> #REF! | S16: =SUM(Q16,R16) -> #REF! | T16: =SUM(L16,Q16) -> #REF! | U16: =SUM(I16,N16,S16) -> #REF! | V16: =SUM(#REF!, 'Quarter 2'!V16, 'Quarter 3'!V16, 'Quarter 4'!V16) -> #REF! | W16: =SUM(#REF!, 'Quarter 2'!W16, 'Quarter 3'!W16, 'Quarter 4'!W16) -> #REF! | X16: =SUM(#REF!, 'Quarter 2'!X16, 'Quarter 3'!X16, 'Quarter 4'!X16) -> #REF! | Y16: =SUM(#REF!, 'Quarter 2'!Y16, 'Quarter 3'!Y16, 'Quarter 4'!Y16) -> #REF! | Z16: =SUM(X16,Y16) -> #REF! | AA16: =SUM(#REF!, 'Quarter 2'!AA16, 'Quarter 3'!AA16, 'Quarter 4'!AA16) -> #REF! | AB16: =IFERROR(V16/J16, 0) -> 0 | AC16: =IFERROR(W16/K16, 0) -> 0 | AD16: =IFERROR(Z16/O16, 0) -> 0 | AE16: =IFERROR(AA16/P16, 0) -> 0 | AF16: =IFERROR(SUM(V16,W16,Z16,AA16)/SUM(L16,Q16), 0) -> 0 | AG16: =SUM(#REF!, 'Quarter 2'!AG16, 'Quarter 3'!AG16, 'Quarter 4'!AG16) -> #REF! | AH16: =SUM(#REF!, 'Quarter 2'!AH16, 'Quarter 3'!AH16, 'Quarter 4'!AH16) -> #REF! | AI16: =SUM(#REF!, 'Quarter 2'!AI16, 'Quarter 3'!AI16, 'Quarter 4'!AI16) -> #REF! | AJ16: =SUM(#REF!, 'Quarter 2'!AJ16, 'Quarter 3'!AJ16, 'Quarter 4'!AJ16) -> #REF! | AK16: =SUM(#REF!, 'Quarter 2'!AK16, 'Quarter 3'!AK16, 'Quarter 4'!AK16) -> #REF! | AL16: =SUM(#REF!, 'Quarter 2'!AL16, 'Quarter 3'!AL16, 'Quarter 4'!AL16) -> #REF! | AM16: =SUM(AG16,AH16,AI16) -> #REF! | AN16: =SUM(#REF!, 'Quarter 2'!AO16, 'Quarter 3'!AN16, 'Quarter 4'!AN16) -> #REF! | AO16: =IFERROR((AN16/B16)*1000000, 0) -> 0
